<?xml version="1.0" ?>
<!-- =================================================================================== -->
<!-- |    This document was autogenerated by xacro from vp6242_with_solder_lead.xacro  | -->
<!-- |    EDITING THIS FILE BY HAND IS NOT RECOMMENDED                                 | -->
<!-- =================================================================================== -->
<robot name="vp6242_with_solder_lead" xmlns:xacro="http://www.ros.org/wiki/xacro">
  <gazebo>
    <plugin filename="libgazebo_ros_control.so" name="ros_control">
      <robotNamespace>/vp6242</robotNamespace>
    </plugin>
  </gazebo>
  <gazebo reference="base_link">
    <material>Gazebo/Blue</material>
    <gravity>false</gravity>
    <selfCollide>false</selfCollide>
  </gazebo>
  <gazebo reference="link1">
    <gravity>false</gravity>
    <selfCollide>false</selfCollide>
  </gazebo>
  <gazebo reference="link2">
    <gravity>false</gravity>
    <selfCollide>false</selfCollide>
  </gazebo>
  <gazebo reference="link3">
    <gravity>false</gravity>
    <selfCollide>false</selfCollide>
  </gazebo>
  <gazebo reference="link4">
    <gravity>false</gravity>
    <selfCollide>false</selfCollide>
  </gazebo>
  <gazebo reference="link5">
    <gravity>false</gravity>
    <selfCollide>false</selfCollide>
  </gazebo>
  <gazebo reference="link6">
    <gravity>false</gravity>
    <selfCollide>false</selfCollide>
  </gazebo>
  <link name="world"/>
  <link name="base_link">
    <visual>
      <geometry>
        <mesh filename="package://vp6242_description/meshes/visual/base.dae" scale="0.001 0.001 0.001"/>
      </geometry>
      <origin rpy="-1.570796 3.141592 0" xyz="0 0 0"/>
    </visual>
    <collision>
      <geometry>
        <mesh filename="package://vp6242_description/meshes/collision/base.dae" scale="0.001 0.001 0.001"/>
      </geometry>
      <origin rpy="-1.570796 3.141592 0" xyz="0 0 0"/>
    </collision>
    <inertial>
      <origin rpy="0 0 0" xyz="0 0 0.0775"/>
      <mass value="1"/>
      <inertia ixx="1.0" ixy="0.0" ixz="0.0" iyy="1.0" iyz="0.0" izz="1.0"/>
    </inertial>
  </link>
  <link name="link1">
    <visual>
      <geometry>
        <mesh filename="package://vp6242_description/meshes/visual/link1.dae" scale="0.001 0.001 0.001"/>
      </geometry>
      <origin rpy="-1.570796 3.141592 0" xyz="0 0 0"/>
    </visual>
    <collision>
      <geometry>
        <mesh filename="package://vp6242_description/meshes/collision/link1.dae" scale="0.001 0.001 0.001"/>
      </geometry>
      <origin rpy="-1.570796 3.141592 0" xyz="0 0 0"/>
    </collision>
    <inertial>
      <origin rpy="0 0 0" xyz="0 0 0.0625"/>
      <mass value="1"/>
      <inertia ixx="1.0" ixy="0.0" ixz="0.0" iyy="1.0" iyz="0.0" izz="1.0"/>
    </inertial>
  </link>
  <link name="link2">
    <visual>
      <geometry>
        <mesh filename="package://vp6242_description/meshes/visual/link2.dae" scale="0.001 0.001 0.001"/>
      </geometry>
      <origin rpy="-1.570796 3.141592 0" xyz="0 0 0"/>
    </visual>
    <collision>
      <geometry>
        <mesh filename="package://vp6242_description/meshes/collision/link2.dae" scale="0.001 0.001 0.001"/>
      </geometry>
      <origin rpy="-1.570796 3.141592 0" xyz="0 0 0"/>
    </collision>
    <inertial>
      <origin rpy="0 0 0" xyz="0 0 0.105"/>
      <mass value="1"/>
      <inertia ixx="1.0" ixy="0.0" ixz="0.0" iyy="1.0" iyz="0.0" izz="1.0"/>
    </inertial>
  </link>
  <link name="link3">
    <visual>
      <geometry>
        <mesh filename="package://vp6242_description/meshes/visual/link3.dae" scale="0.001 0.001 0.001"/>
      </geometry>
      <origin rpy="-1.570796 1.570796 0" xyz="0 0 0"/>
    </visual>
    <collision>
      <geometry>
        <mesh filename="package://vp6242_description/meshes/collision/link3.dae" scale="0.001 0.001 0.001"/>
      </geometry>
      <origin rpy="-1.570796 1.570796 0" xyz="0 0 0"/>
    </collision>
    <inertial>
      <origin rpy="0 0 0" xyz="-0.075 0 0"/>
      <mass value="1"/>
      <inertia ixx="1.0" ixy="0.0" ixz="0.0" iyy="1.0" iyz="0.0" izz="1.0"/>
    </inertial>
  </link>
  <link name="link4">
    <visual>
      <geometry>
        <mesh filename="package://vp6242_description/meshes/visual/link4.dae" scale="0.001 0.001 0.001"/>
      </geometry>
      <origin rpy="0 1.570796 1.570796" xyz="0 0 0.085"/>
    </visual>
    <collision>
      <geometry>
        <mesh filename="package://vp6242_description/meshes/collision/link4.dae" scale="0.001 0.001 0.001"/>
      </geometry>
      <origin rpy="0 1.570796 1.570796" xyz="0 0 0.085"/>
    </collision>
    <inertial>
      <origin rpy="0 0 0" xyz="0 0 0.13"/>
      <mass value="1"/>
      <inertia ixx="1.0" ixy="0.0" ixz="0.0" iyy="1.0" iyz="0.0" izz="1.0"/>
    </inertial>
  </link>
  <link name="link5">
    <visual>
      <geometry>
        <mesh filename="package://vp6242_description/meshes/visual/link5.dae" scale="0.001 0.001 0.001"/>
      </geometry>
      <origin rpy="0 1.570796 1.570796" xyz="0 0 0.0"/>
    </visual>
    <collision>
      <geometry>
        <mesh filename="package://vp6242_description/meshes/collision/link5.dae" scale="0.001 0.001 0.001"/>
      </geometry>
      <origin rpy="0 1.570796 1.570796" xyz="0 0 0.0"/>
    </collision>
    <inertial>
      <origin rpy="0 0 0" xyz="0 0 0"/>
      <mass value="1"/>
      <inertia ixx="1.0" ixy="0.0" ixz="0.0" iyy="1.0" iyz="0.0" izz="1.0"/>
    </inertial>
  </link>
  <link name="link6">
    <visual>
      <geometry>
        <cylinder length="0.01" radius="0.0205"/>
      </geometry>
      <origin rpy="0 0 0" xyz="0.0 0.0 -0.005"/>
      <material name="plate">
        <color rgba="0.1 0.1 0.1 0.8"/>
      </material>
    </visual>
    <collision>
      <geometry>
        <cylinder length="0.01" radius="0.0205"/>
      </geometry>
      <origin rpy="0 0 0" xyz="0.0 0.0 -0.005"/>
    </collision>
    <inertial>
      <origin rpy="0 0 0" xyz="0 0 0"/>
      <mass value="0.2"/>
      <inertia ixx="1.0" ixy="0.0" ixz="0.0" iyy="1.0" iyz="0.0" izz="1.0"/>
    </inertial>
  </link>
  <link name="tool0"/>
  <joint name="world-base" type="fixed">
    <parent link="world"/>
    <child link="base_link"/>
  </joint>
  <joint name="joint1" type="revolute">
    <origin rpy="0 0 0" xyz="0.0 0.0 0.155"/>
    <parent link="base_link"/>
    <child link="link1"/>
    <axis xyz="0 0 1"/>
    <limit effort="100000" lower="-2.792526803" upper="2.792526803" velocity="1.0"/>
    <dynamics damping="0.7"/>
  </joint>
  <joint name="joint2" type="revolute">
    <origin rpy="0 0 0" xyz="0.0 0.0 0.125"/>
    <parent link="link1"/>
    <child link="link2"/>
    <axis xyz="0 1 0"/>
    <limit effort="100000" lower="-2.094395102" upper="2.094395102" velocity="1.0"/>
    <dynamics damping="0.7"/>
  </joint>
  <joint name="joint3" type="revolute">
    <origin rpy="0 0 0" xyz="0.0 0.0 0.210"/>
    <parent link="link2"/>
    <child link="link3"/>
    <axis xyz="0 1 0"/>
    <limit effort="100000" lower="0.331612558" upper="2.792526803" velocity="1.0"/>
    <dynamics damping="0.7"/>
  </joint>
  <joint name="joint4" type="revolute">
    <origin rpy="0 0 0" xyz="-0.075 0.0 0.0"/>
    <parent link="link3"/>
    <child link="link4"/>
    <axis xyz="0 0 1"/>
    <limit effort="100000" lower="-2.792526803" upper="2.792526803" velocity="1.0"/>
    <dynamics damping="0.7"/>
  </joint>
  <joint name="joint5" type="revolute">
    <origin rpy="0 0 0" xyz="0.0 0.0 0.210"/>
    <parent link="link4"/>
    <child link="link5"/>
    <axis xyz="0 1 0"/>
    <limit effort="100000" lower="-2.094395102" upper="2.094395102" velocity="1.0"/>
    <dynamics damping="0.7"/>
  </joint>
  <joint name="joint6" type="revolute">
    <origin rpy="0 0 0" xyz="0.0 0.0 0.07"/>
    <parent link="link5"/>
    <child link="link6"/>
    <axis xyz="0 0 1"/>
    <limit effort="100000" lower="-6.283185307" upper="6.283185307" velocity="1.0"/>
    <dynamics damping="0.7"/>
  </joint>
  <joint name="joint6-tool0" type="fixed">
    <parent link="link6"/>
    <child link="tool0"/>
    <origin rpy="0 0 0" xyz="0 0 0"/>
  </joint>
  <transmission name="tran1" type="transmission_interface/SimpleTransmission">
    <joint name="joint1"/>
    <actuator name="motor1" type="EffortJointInterface"/>
    <mechanicalReduction>1</mechanicalReduction>
  </transmission>
  <transmission name="tran2" type="transmission_interface/SimpleTransmission">
    <joint name="joint2"/>
    <actuator name="motor2" type="EffortJointInterface"/>
    <mechanicalReduction>1</mechanicalReduction>
  </transmission>
  <transmission name="tran3" type="transmission_interface/SimpleTransmission">
    <joint name="joint3"/>
    <actuator name="motor3" type="EffortJointInterface"/>
    <mechanicalReduction>1</mechanicalReduction>
  </transmission>
  <transmission name="tran4" type="transmission_interface/SimpleTransmission">
    <joint name="joint4"/>
    <actuator name="motor4" type="EffortJointInterface"/>
    <mechanicalReduction>1</mechanicalReduction>
  </transmission>
  <transmission name="tran5" type="transmission_interface/SimpleTransmission">
    <joint name="joint5"/>
    <actuator name="motor5" type="EffortJointInterface"/>
    <mechanicalReduction>1</mechanicalReduction>
  </transmission>
  <transmission name="tran6" type="transmission_interface/SimpleTransmission">
    <joint name="joint6"/>
    <actuator name="motor6" type="EffortJointInterface"/>
    <mechanicalReduction>1</mechanicalReduction>
  </transmission>
  <link name="force_sensor_base">
    <visual>
      <geometry>
        <mesh filename="package://hg_parts//vp6242/meshes/force_sensor_holder_base.dae" scale="0.001 0.001 0.001"/>
      </geometry>
      <origin rpy="0 1.570796 1.570796" xyz="0 0 0"/>
    </visual>
    <collision>
      <geometry>
        <sphere radius="0.06"/>
      </geometry>
      <origin rpy="0 0 0" xyz="0 0 0.03"/>
    </collision>
  </link>
  <joint name="tool0_force_sensor" type="fixed">
    <parent link="tool0"/>
    <child link="force_sensor_base"/>
    <origin rpy="0 0 0" xyz="0 0 0"/>
  </joint>
  <link name="clip_base">
    <visual>
      <geometry>
        <mesh filename="package://hg_parts//holder/meshes/clip_base.dae" scale="0.001 0.001 0.001"/>
      </geometry>
      <origin rpy="3.141592 0 1.570796" xyz="-0.01 0 0.015"/>
    </visual>
    <collision>
      <geometry>
        <sphere radius="0.035"/>
      </geometry>
      <origin rpy="0 0 0" xyz="0 0 0.015"/>
    </collision>
  </link>
  <joint name="base_clip_base" type="fixed">
    <parent link="force_sensor_base"/>
    <child link="clip_base"/>
    <origin rpy="0 -0.2 0" xyz="0 0 0.068"/>
  </joint>
  <link name="clip_cover">
    <visual>
      <geometry>
        <mesh filename="package://hg_parts//holder/meshes/clip_cover.dae" scale="0.001 0.001 0.001"/>
      </geometry>
      <origin rpy="0 0 1.570796" xyz="0.01 0 0"/>
    </visual>
    <collision>
      <geometry>
        <sphere radius="0.035"/>
      </geometry>
      <origin rpy="0 0 0" xyz="0 0 0"/>
    </collision>
  </link>
  <joint name="base_cover" type="fixed">
    <parent link="clip_base"/>
    <child link="clip_cover"/>
    <origin rpy="0 0 0" xyz="0 0 0.045"/>
  </joint>
  <link name="lead">
    <visual>
      <geometry>
        <cylinder length="0.095" radius="0.01"/>
      </geometry>
      <material name="Cyan">
        <color rgba="0 1.0 1.0 1.0"/>
      </material>
      <origin rpy="0 0 0" xyz="0 0 -0.0475"/>
    </visual>
    <collision>
      <geometry>
        <cylinder length="0.11" radius="0.011"/>
      </geometry>
      <origin rpy="0 0 0" xyz="0 0 -0.0475"/>
    </collision>
  </link>
  <joint name="base_clip_lead" type="fixed">
    <parent link="clip_base"/>
    <child link="lead"/>
    <origin rpy="0 1.570796 0" xyz="0.05 0 0.03"/>
  </joint>
</robot>

